<?xml version="1.0"?>
<robot name="exam_robot">
  
  <!-- Материалы -->
  <material name="blue">
    <color rgba="0 0 0.8 1"/>
  </material>
  <material name="black">
    <color rgba="0.1 0.1 0.1 1"/>
  </material>
  <material name="red">
    <color rgba="0.8 0 0 1"/>
  </material>
  <material name="gray">
    <color rgba="0.5 0.5 0.5 1"/>
  </material>

  <!-- Корпус -->
  <link name="base_link">
    <visual>
      <geometry>
        <box size="0.4 0.3 0.1"/>
      </geometry>
      <material name="blue"/>
    </visual>
    <collision>
      <geometry>
        <box size="0.4 0.3 0.1"/>
      </geometry>
    </collision>
    <inertial>
      <mass value="1.0"/>
      <inertia ixx="0.01" ixy="0" ixz="0" iyy="0.01" iyz="0" izz="0.01"/>
    </inertial>
  </link>

  <!-- Левое колесо -->
  <link name="left_wheel">
    <visual>
      <geometry>
        <cylinder radius="0.08" length="0.04"/>
      </geometry>
      <origin rpy="1.5708 0 0"/>
      <material name="black"/>
    </visual>
    <collision>
      <geometry>
        <cylinder radius="0.08" length="0.04"/>
      </geometry>
    </collision>
    <inertial>
      <mass value="0.2"/>
      <inertia ixx="0.001" ixy="0" ixz="0" iyy="0.001" iyz="0" izz="0.001"/>
    </inertial>
  </link>

  <!-- Правое колесо -->
  <link name="right_wheel">
    <visual>
      <geometry>
        <cylinder radius="0.08" length="0.04"/>
      </geometry>
      <origin rpy="1.5708 0 0"/>
      <material name="black"/>
    </visual>
    <collision>
      <geometry>
        <cylinder radius="0.08" length="0.04"/>
      </geometry>
    </collision>
    <inertial>
      <mass value="0.2"/>
      <inertia ixx="0.001" ixy="0" ixz="0" iyy="0.001" iyz="0" izz="0.001"/>
    </inertial>
  </link>

  <!-- Датчик (красный кубик на передней части) -->
  <link name="sensor_link">
    <visual>
      <geometry>
        <box size="0.1 0.1 0.1"/>
      </geometry>
      <material name="red"/>
    </visual>
    <collision>
      <geometry>
        <box size="0.1 0.1 0.1"/>
      </geometry>
    </collision>
    <inertial>
      <mass value="0.1"/>
      <inertia ixx="0.0001" ixy="0" ixz="0" iyy="0.0001" iyz="0" izz="0.0001"/>
    </inertial>
  </link>

  <!-- Сочленения -->
  <joint name="base_to_left_wheel" type="continuous">
    <parent link="base_link"/>
    <child link="left_wheel"/>
    <origin xyz="-0.1 0.17 0" rpy="1.5708 0 0"/>
    <axis xyz="0 0 1"/>
  </joint>

  <joint name="base_to_right_wheel" type="continuous">
    <parent link="base_link"/>
    <child link="right_wheel"/>
    <origin xyz="-0.1 -0.17 0" rpy="1.5708 0 0"/>
    <axis xyz="0 0 1"/>
  </joint>

  <joint name="base_to_sensor" type="fixed">
    <parent link="base_link"/>
    <child link="sensor_link"/>
    <origin xyz="0.2 0 0.05" rpy="0 0 0"/>
  </joint>

</robot>